Workbook

Sheet Project Overview
A1: Sales Performance Analytics Dashboard
A4: Business Intelligence & Reporting Project
A6: Project Overview
A7: Designed and developed an Excel-based analytics dashboard to monitor sales performance, analyze KPIs, and generate actionable business insights from operational datasets.
A10: Objectives
A11: • Analyze sales representative performance and target achievement • Build interactive dashboards for business reporting • Identify sales trends and operational insights • Automate reporting workflows using dynamic Excel features
A15: Tools & Technologies
A16: Microsoft Excel, Pivot Tables, Pivot Charts, Conditional Formatting, Data Cleaning, Dashboard Design, KPI Tracking
A18: Key Features
A19: • Interactive KPI dashboard • Sales representative performance analysis • Target vs Achievement tracking • Automated reporting summaries • Dynamic charts and slicers
A23: Business Insights
A24: • Identified high-performing sales regions and representatives • Analyzed target achievement percentages across teams • Improved reporting visibility and decision-making insights

Sheet Raw_Data
A1: Order_ID | B1: Order_Date | C1: Customer_ID | D1: Region | E1: Product_SKU | F1: Product_Name | G1: Product_Category | H1: Quantity | I1: Unit_Price | J1: Discount | K1: Rep_ID
A2: ORD-5162 | B2: 46010 | C2: CUST-1022 | D2: north | E2: SKU-1006 | F2: Pen Set | G2: Stationery | H2: 5 | I2: 450 | J2: 0.2 | K2: R004
A3: ORD-5201 | B3: 04/24/2026 | C3: CUST-1000 | D3: central | E3: SKU-1003 | F3: Office Chair | G3: Furniture | H3: 7 | I3: 12000 | J3: 0.1 | K3: R003
A4: ORD-5169 | B4: 46128 | C4: CUST-1015 | D4: N. | E4: SKU-1001 | F4: Laptop | G4: Electronics | H4: 12 | I4: 65000 | J4: 0.05 | K4: R003
A5: ORD-5168 | B5: 04/04/2026 | C5: CUST-1028 | D5: EAST | E5: SKU-1006 | F5: Pen Set | G5: Stationery | H5: 8 | I5: 450 | J5: 0.2 | K5: R003
A6: ORD-5098 | B6: 03/20/2026 | C6: CUST-1004 | D6: west | E6: SKU-1006 | F6: Pen Set | G6: Stationery | H6: 10 | I6: 450 | J6: 0.2 | K6: R003
A7: ORD-5209 | B7: 20-04-2026 | C7: CUST-1029 | D7: East | E7: SKU-1003 | F7: Office Chair | G7: Furniture | H7: 7 | I7: 12000 | J7: 0.15 | K7: R006
A8: ORD-5145 | B8: 2026-04-15 | C8: CUST-1032 | D8: EAST | E8: SKU-1001 | F8: Laptop | G8: Electronics | H8: 6 | I8: 65000 | J8: 0.2 | K8: R002
A9: ORD-5130 | B9: 46036 | C9: CUST-1007 | D9: North | E9: SKU-1008 | F9: Keyboard | G9: Electronics | H9: 12 | I9: 3500 | J9: 0.1 | K9: R005
A10: ORD-5090 | B10: 2026-01-01 | C10: CUST-1014 | D10: West | E10: SKU-1001 | F10: Laptop | G10: Electronics | H10: 6 | I10: 65000 | J10: 0.2 | K10: R006
A11: ORD-5051 | B11: 12/06/2025 | C11: CUST-1014 | D11: East | E11: SKU-1003 | F11: Office Chair | G11: Furniture | H11: 12 | I11: 12000 | J11: 0.2 | K11: R004
A12: ORD-5024 | B12: 46010 | C12: CUST-1013 | D12: north | E12: SKU-1010 | F12: Whiteboard | G12: Office Supplies | H12: 12 | I12: 2200 | J12: 0 | K12: R005
A13: ORD-5181 | B13: 46014 | C13: CUST-1038 | D13: Nort h | E13: SKU-1006 | F13: Pen Set | G13: Stationery | H13: 12 | I13: 450 | J13: 0.2 | K13: R002
A14: ORD-5172 | B14: 04/29/2026 | C14: CUST-1023 | E14: SKU-1004 | F14: Standing Desk | G14: Furniture | H14: 2 | I14: 28000 | K14: R004
A15: ORD-5114 | B15: 45965 | C15: CUST-1015 | D15: CENTRAL | E15: SKU-1006 | F15: Pen Set | G15: Stationery | H15: 1 | I15: 450 | J15: 0.25 | K15: R001
A16: ORD-5154 | B16: 2025-12-06 | C16: CUST-1028 | D16: Centr al | E16: SKU-1001 | F16: Laptop | G16: Electronics | H16: 2 | K16: R002
A17: ORD-5061 | B17: N/A | C17: CUST-1038 | D17: N. | E17: SKU-1010 | F17: Whiteboard | G17: Office Supplies | H17: 1 | I17: 2200 | J17: 0.25 | K17: R006
A18: ORD-5129 | B18: 46096 | C18: CUST-1002 | D18: SOUTH | E18: SKU-1007 | F18: Monitor | G18: Electronics | H18: 10 | I18: 18000 | J18: 0.1 | K18: R003
A19: ORD-5027 | B19: 46014 | C19: CUST-1015 | D19: S. | E19: SKU-1007 | F19: Monitor | G19: Electronics | H19: 3 | I19: 18000 | J19: 0.05 | K19: R001
A20: ORD-5064 | B20: 45984 | C20: CUST-1028 | D20: SOUTH | E20: SKU-1008 | F20: Keyboard | G20: Electronics | H20: 10 | I20: 3500 | J20: 0 | K20: R003
A21: ORD-5124 | B21: 24-03-2026 | C21: CUST-1038 | D21: S. | E21: SKU-1001 | F21: Laptop | G21: Electronics | H21: 3 | I21: 65000 | J21: 0.15 | K21: R001
A22: ORD-5170 | B22: 2026-01-06 | C22: CUST-1013 | D22: Centr al | E22: SKU-1005 | F22: Notebook | G22: Stationery | H22: 12 | I22: 250 | J22: 0 | K22: R001
A23: ORD-5153 | B23: 45969 | C23: CUST-1006 | E23: SKU-1003 | F23: Office Chair | G23: Furniture | H23: 3 | J23: 0.2 | K23: R006
A24: ORD-5050 | B24: 03/05/2026 | C24: CUST-1017 | D24: west | E24: SKU-1002 | F24: Headphones | G24: Electronics | H24: 12 | I24: 4500 | J24: 0.25 | K24: R001
A25: ORD-5049 | B25: 2026-03-10 | C25: CUST-1035 | D25: west | E25: SKU-1003 | F25: Office Chair | G25: Furniture | H25: 12 | I25: 12000 | J25: 0.15 | K25: R005
A26: ORD-5103 | B26: 02/15/2026 | C26: CUST-1012 | D26: Nort h | E26: SKU-1009 | F26: Filing Cabinet | G26: Furniture | H26: 6 | I26: 9500 | J26: 0.15 | K26: R004
A27: ORD-5089 | B27: 46085 | C27: CUST-1021 | D27: central | E27: SKU-1009 | F27: Filing Cabinet | G27: Furniture | H27: 7 | I27: 9500 | K27: R006
A28: ORD-5111 | B28: 46063 | C28: CUST-1012 | D28: N. | E28: SKU-1008 | F28: Keyboard | G28: Electronics | H28: 2 | I28: 3500 | J28: 0.05 | K28: R001
A29: ORD-5100 | B29: 2026-04-18 | C29: CUST-1017 | D29: North | E29: SKU-1010 | F29: Whiteboard | G29: Office Supplies | H29: 11 | I29: 2200 | J29: 0.2 | K29: R003
A30: ORD-5022 | B30: 12/31/2025 | C30: CUST-1026 | D30: WEST | E30: SKU-1008 | F30: Keyboard | G30: Electronics | H30: 4 | I30: 3500 | K30: R001
A31: ORD-5091 | B31: 04/16/2026 | C31: CUST-1031 | D31: north | E31: SKU-1003 | F31: Office Chair | G31: Furniture | H31: 9 | I31: 12000 | J31: 0 | K31: R004
A32: ORD-5016 | B32: 04/26/2026 | C32: CUST-1019 | D32: East | E32: SKU-1006 | F32: Pen Set | G32: Stationery | H32: 8 | I32: 450 | K32: R001
A33: ORD-5177 | B33: 45982 | C33: CUST-1012 | D33: central | E33: SKU-1005 | F33: Notebook | G33: Stationery | H33: 3 | I33: 250 | J33: 0 | K33: R006
A34: ORD-5159 | B34: 01/28/2026 | C34: CUST-1006 | D34: CENTRAL | E34: SKU-1006 | F34: Pen Set | G34: Stationery | H34: 3 | J34: 0.1 | K34: R006
A35: ORD-5073 | B35: 46106 | C35: CUST-1005 | D35: SOUTH | E35: SKU-1002 | F35: Headphones | G35: Electronics | H35: 9 | I35: 4500 | J35: 0.1 | K35: R005
A36: ORD-5110 | B36: 2025-12-26 | C36: CUST-1028 | D36: SOUTH | E36: SKU-1006 | F36: Pen Set | G36: Stationery | H36: 2 | I36: 450 | J36: 0.15 | K36: R001
A37: ORD-5041 | B37: 45979 | C37: CUST-1039 | D37: east | E37: SKU-1002 | F37: Headphones | G37: Electronics | H37: 12 | I37: 4500 | J37: 0.15 | K37: R004
A38: ORD-5163 | B38: 01/26/2026 | C38: CUST-1031 | D38: WEST | E38: SKU-1006 | F38: Pen Set | G38: Stationery | H38: 9 | I38: 450 | J38: 0.2 | K38: R005
A39: ORD-5071 | B39: 45975 | C39: CUST-1008 | D39: WEST | E39: SKU-1002 | F39: Headphones | G39: Electronics | H39: 1 | I39: 4500 | J39: 0.1 | K39: R001
A40: ORD-5219 | B40: 2026-01-16 | C40: CUST-1034 | D40: West | E40: SKU-1009 | F40: Filing Cabinet | G40: Furniture | H40: 7 | I40: 9500 | J40: 0.15 | K40: R002
...

Sheet Reps
A1: Rep_ID | B1: Account_Manager | C1: Email | D1: Region_Assigned
A2: R001 | B2: Anita Sharma | C2: anita.s@company.com | D2: North
A3: R002 | B3: Rahul Verma | C3: rahul.v@company.com | D3: South
A4: R003 | B4: Priya Iyer | C4: priya.i@company.com | D4: East
A5: R004 | B5: Karan Mehta | C5: karan.m@company.com | D5: West
A6: R005 | B6: Sneha Reddy | C6: sneha.r@company.com | D6: Central
A7: R006 | B7: Vikram Nair | C7: vikram.n@company.com | D7: South

Sheet Targets
A1: Region | B1: Nov-2025 | C1: Dec-2025 | D1: Jan-2026 | E1: Feb-2026 | F1: Mar-2026 | G1: Apr-2026
A2: North | B2: 850000 | C2: 900000 | D2: 920000 | E2: 880000 | F2: 950000 | G2: 1000000
A3: South | B3: 780000 | C3: 820000 | D3: 850000 | E3: 800000 | F3: 880000 | G3: 920000
A4: East | B4: 620000 | C4: 650000 | D4: 680000 | E4: 660000 | F4: 700000 | G4: 740000
A5: West | B5: 700000 | C5: 730000 | D5: 760000 | E5: 740000 | F5: 790000 | G5: 830000
A6: Central | B6: 540000 | C6: 570000 | D6: 600000 | E6: 580000 | F6: 620000 | G6: 660000
A8: Note: | B8: Targets are in INR. Candidate should compute Achievement % = Actual / Target.

Sheet Cleaned_Data
A1: Order_ID | B1: Order_Date | C1: Customer_ID | D1: Region | E1: Product_SKU | F1: Product_Name | G1: Product_Category | H1: Quantity | I1: Unit_Price | J1: Discount | K1: Rep_ID | L1: Duplicate Flag | M1: Net Revenue | N1: Data_Quality_Flag | O1: Account Manager | P1: Month
A2: ORD-5162 | B2: =IFERROR(IFERROR(INT(VALUE(Raw_Data!B2)), DATE(RIGHT(TRIM(Raw_Data!B2),4), MID(TRIM(Raw_Data!B2),4,2), LEFT(TRIM(Raw_Data!B2),2))), "NA") -> 46010 | C2: CUST-1022 | D2: =IF(OR(LOWER(TRIM(Raw_Data!D2))="north",LOWER(TRIM(Raw_Data!D2))="n.",LOWER(SUBSTITUTE(TRIM(Raw_Data!D2)," ",""))="north"),"North",IF(OR(LOWER(TRIM(Raw_Data!D2))="south",LOWER(TRIM(Raw_Data!D2))="s."),"South",IF(OR(LOWER(TRIM(Raw_Data!D2))="east",LOWER(TRIM(Raw_Data!D2))="e."),"East",IF(OR(LOWER(TRIM(Raw_Data!D2))="west",LOWER(TRIM(Raw_Data!D2))="w."),"West",IF(OR(LOWER(TRIM(Raw_Data!D2))="central",LOWER(TRIM(Raw_Data!D2))="c."),"Central","Unknown"))))) -> North | E2: SKU-1006 | F2: Pen Set | G2: Stationery | H2: =IFERROR(VALUE(Raw_Data!H2),0) -> 5 | I2: =IFERROR(VALUE(Raw_Data!I2),0) -> 450 | J2: =IFERROR(VALUE(Raw_Data!J2),0) -> 0.2 | K2: R004 | L2: =IF(COUNTIF($A$2:A2, A2)>1, "Duplicate", "Valid") -> Valid | M2: =H2*I2*(1-J2) -> 1800 | N2: =IF(COUNTIF($A$2:A2, A2)>1, "Duplicate", IF(OR(B2="NA", ISERROR(B2), ISTEXT(B2)), "Invalid Date", IF(OR(C2=0, E2=0, H2=0, I2=0, J2=0), "Missing Data", "OK"))) -> OK | O2: =IFERROR(INDEX(Reps!$B:$B, MATCH(K2, Reps!$A:$A, 0)), "Not Found") -> Karan Mehta | P2: =IFERROR(TEXT(B2, "mmmm"),"") -> December
A3: ORD-5201 | B3: =IFERROR(IFERROR(INT(VALUE(Raw_Data!B3)), DATE(RIGHT(TRIM(Raw_Data!B3),4), MID(TRIM(Raw_Data!B3),4,2), LEFT(TRIM(Raw_Data!B3),2))), "NA") -> 46725 | C3: CUST-1000 | D3: =IF(OR(LOWER(TRIM(Raw_Data!D3))="north",LOWER(TRIM(Raw_Data!D3))="n.",LOWER(SUBSTITUTE(TRIM(Raw_Data!D3)," ",""))="north"),"North",IF(OR(LOWER(TRIM(Raw_Data!D3))="south",LOWER(TRIM(Raw_Data!D3))="s."),"South",IF(OR(LOWER(TRIM(Raw_Data!D3))="east",LOWER(TRIM(Raw_Data!D3))="e."),"East",IF(OR(LOWER(TRIM(Raw_Data!D3))="west",LOWER(TRIM(Raw_Data!D3))="w."),"West",IF(OR(LOWER(TRIM(Raw_Data!D3))="central",LOWER(TRIM(Raw_Data!D3))="c."),"Central","Unknown"))))) -> Central | E3: SKU-1003 | F3: Office Chair | G3: Furniture | H3: =IFERROR(VALUE(Raw_Data!H3),0) -> 7 | I3: =IFERROR(VALUE(Raw_Data!I3),0) -> 12000 | J3: =IFERROR(VALUE(Raw_Data!J3),0) -> 0.1 | K3: R003 | L3: =IF(COUNTIF($A$2:A3, A3)>1, "Duplicate", "Valid") -> Valid | M3: =H3*I3*(1-J3) -> 75600 | N3: =IF(COUNTIF($A$2:A3, A3)>1, "Duplicate", IF(OR(B3="NA", ISERROR(B3), ISTEXT(B3)), "Invalid Date", IF(OR(C3=0, E3=0, H3=0, I3=0, J3=0), "Missing Data", "OK"))) -> OK | O3: =IFERROR(INDEX(Reps!$B:$B, MATCH(K3, Reps!$A:$A, 0)), "Not Found") -> Priya Iyer | P3: =IFERROR(TEXT(B3, "mmmm"),"") -> December
A4: ORD-5169 | B4: =IFERROR(IFERROR(INT(VALUE(Raw_Data!B4)), DATE(RIGHT(TRIM(Raw_Data!B4),4), MID(TRIM(Raw_Data!B4),4,2), LEFT(TRIM(Raw_Data!B4),2))), "NA") -> 46128 | C4: CUST-1015 | D4: =IF(OR(LOWER(TRIM(Raw_Data!D4))="north",LOWER(TRIM(Raw_Data!D4))="n.",LOWER(SUBSTITUTE(TRIM(Raw_Data!D4)," ",""))="north"),"North",IF(OR(LOWER(TRIM(Raw_Data!D4))="south",LOWER(TRIM(Raw_Data!D4))="s."),"South",IF(OR(LOWER(TRIM(Raw_Data!D4))="east",LOWER(TRIM(Raw_Data!D4))="e."),"East",IF(OR(LOWER(TRIM(Raw_Data!D4))="west",LOWER(TRIM(Raw_Data!D4))="w."),"West",IF(OR(LOWER(TRIM(Raw_Data!D4))="central",LOWER(TRIM(Raw_Data!D4))="c."),"Central","Unknown"))))) -> North | E4: SKU-1001 | F4: Laptop | G4: Electronics | H4: =IFERROR(VALUE(Raw_Data!H4),0) -> 12 | I4: =IFERROR(VALUE(Raw_Data!I4),0) -> 65000 | J4: =IFERROR(VALUE(Raw_Data!J4),0) -> 0.05 | K4: R003 | L4: =IF(COUNTIF($A$2:A4, A4)>1, "Duplicate", "Valid") -> Valid | M4: =H4*I4*(1-J4) -> 741000 | N4: =IF(COUNTIF($A$2:A4, A4)>1, "Duplicate", IF(OR(B4="NA", ISERROR(B4), ISTEXT(B4)), "Invalid Date", IF(OR(C4=0, E4=0, H4=0, I4=0, J4=0), "Missing Data", "OK"))) -> OK | O4: =IFERROR(INDEX(Reps!$B:$B, MATCH(K4, Reps!$A:$A, 0)), "Not Found") -> Priya Iyer | P4: =IFERROR(TEXT(B4, "mmmm"),"") -> April
A5: ORD-5168 | B5: =IFERROR(IFERROR(INT(VALUE(Raw_Data!B5)), DATE(RIGHT(TRIM(Raw_Data!B5),4), MID(TRIM(Raw_Data!B5),4,2), LEFT(TRIM(Raw_Data!B5),2))), "NA") -> 46116 | C5: CUST-1028 | D5: =IF(OR(LOWER(TRIM(Raw_Data!D5))="north",LOWER(TRIM(Raw_Data!D5))="n.",LOWER(SUBSTITUTE(TRIM(Raw_Data!D5)," ",""))="north"),"North",IF(OR(LOWER(TRIM(Raw_Data!D5))="south",LOWER(TRIM(Raw_Data!D5))="s."),"South",IF(OR(LOWER(TRIM(Raw_Data!D5))="east",LOWER(TRIM(Raw_Data!D5))="e."),"East",IF(OR(LOWER(TRIM(Raw_Data!D5))="west",LOWER(TRIM(Raw_Data!D5))="w."),"West",IF(OR(LOWER(TRIM(Raw_Data!D5))="central",LOWER(TRIM(Raw_Data!D5))="c."),"Central","Unknown"))))) -> East | E5: SKU-1006 | F5: Pen Set | G5: Stationery | H5: =IFERROR(VALUE(Raw_Data!H5),0) -> 8 | I5: =IFERROR(VALUE(Raw_Data!I5),0) -> 450 | J5: =IFERROR(VALUE(Raw_Data!J5),0) -> 0.2 | K5: R003 | L5: =IF(COUNTIF($A$2:A5, A5)>1, "Duplicate", "Valid") -> Valid | M5: =H5*I5*(1-J5) -> 2880 | N5: =IF(COUNTIF($A$2:A5, A5)>1, "Duplicate", IF(OR(B5="NA", ISERROR(B5), ISTEXT(B5)), "Invalid Date", IF(OR(C5=0, E5=0, H5=0, I5=0, J5=0), "Missing Data", "OK"))) -> OK | O5: =IFERROR(INDEX(Reps!$B:$B, MATCH(K5, Reps!$A:$A, 0)), "Not Found") -> Priya Iyer | P5: =IFERROR(TEXT(B5, "mmmm"),"") -> April
A6: ORD-5098 | B6: =IFERROR(IFERROR(INT(VALUE(Raw_Data!B6)), DATE(RIGHT(TRIM(Raw_Data!B6),4), MID(TRIM(Raw_Data!B6),4,2), LEFT(TRIM(Raw_Data!B6),2))), "NA") -> 46602 | C6: CUST-1004 | D6: =IF(OR(LOWER(TRIM(Raw_Data!D6))="north",LOWER(TRIM(Raw_Data!D6))="n.",LOWER(SUBSTITUTE(TRIM(Raw_Data!D6)," ",""))="north"),"North",IF(OR(LOWER(TRIM(Raw_Data!D6))="south",LOWER(TRIM(Raw_Data!D6))="s."),"South",IF(OR(LOWER(TRIM(Raw_Data!D6))="east",LOWER(TRIM(Raw_Data!D6))="e."),"East",IF(OR(LOWER(TRIM(Raw_Data!D6))="west",LOWER(TRIM(Raw_Data!D6))="w."),"West",IF(OR(LOWER(TRIM(Raw_Data!D6))="central",LOWER(TRIM(Raw_Data!D6))="c."),"Central","Unknown"))))) -> West | E6: SKU-1006 | F6: Pen Set | G6: Stationery | H6: =IFERROR(VALUE(Raw_Data!H6),0) -> 10 | I6: =IFERROR(VALUE(Raw_Data!I6),0) -> 450 | J6: =IFERROR(VALUE(Raw_Data!J6),0) -> 0.2 | K6: R003 | L6: =IF(COUNTIF($A$2:A6, A6)>1, "Duplicate", "Valid") -> Valid | M6: =H6*I6*(1-J6) -> 3600 | N6: =IF(COUNTIF($A$2:A6, A6)>1, "Duplicate", IF(OR(B6="NA", ISERROR(B6), ISTEXT(B6)), "Invalid Date", IF(OR(C6=0, E6=0, H6=0, I6=0, J6=0), "Missing Data", "OK"))) -> OK | O6: =IFERROR(INDEX(Reps!$B:$B, MATCH(K6, Reps!$A:$A, 0)), "Not Found") -> Priya Iyer | P6: =IFERROR(TEXT(B6, "mmmm"),"") -> August
A7: ORD-5209 | B7: =IFERROR(IFERROR(INT(VALUE(Raw_Data!B7)), DATE(RIGHT(TRIM(Raw_Data!B7),4), MID(TRIM(Raw_Data!B7),4,2), LEFT(TRIM(Raw_Data!B7),2))), "NA") -> 46132 | C7: CUST-1029 | D7: =IF(OR(LOWER(TRIM(Raw_Data!D7))="north",LOWER(TRIM(Raw_Data!D7))="n.",LOWER(SUBSTITUTE(TRIM(Raw_Data!D7)," ",""))="north"),"North",IF(OR(LOWER(TRIM(Raw_Data!D7))="south",LOWER(TRIM(Raw_Data!D7))="s."),"South",IF(OR(LOWER(TRIM(Raw_Data!D7))="east",LOWER(TRIM(Raw_Data!D7))="e."),"East",IF(OR(LOWER(TRIM(Raw_Data!D7))="west",LOWER(TRIM(Raw_Data!D7))="w."),"West",IF(OR(LOWER(TRIM(Raw_Data!D7))="central",LOWER(TRIM(Raw_Data!D7))="c."),"Central","Unknown"))))) -> East | E7: SKU-1003 | F7: Office Chair | G7: Furniture | H7: =IFERROR(VALUE(Raw_Data!H7),0) -> 7 | I7: =IFERROR(VALUE(Raw_Data!I7),0) -> 12000 | J7: =IFERROR(VALUE(Raw_Data!J7),0) -> 0.15 | K7: R006 | L7: =IF(COUNTIF($A$2:A7, A7)>1, "Duplicate", "Valid") -> Valid | M7: =H7*I7*(1-J7) -> 71400 | N7: =IF(COUNTIF($A$2:A7, A7)>1, "Duplicate", IF(OR(B7="NA", ISERROR(B7), ISTEXT(B7)), "Invalid Date", IF(OR(C7=0, E7=0, H7=0, I7=0, J7=0), "Missing Data", "OK"))) -> OK | O7: =IFERROR(INDEX(Reps!$B:$B, MATCH(K7, Reps!$A:$A, 0)), "Not Found") -> Vikram Nair | P7: =IFERROR(TEXT(B7, "mmmm"),"") -> April
A8: ORD-5145 | B8: =IFERROR(IFERROR(INT(VALUE(Raw_Data!B8)), DATE(RIGHT(TRIM(Raw_Data!B8),4), MID(TRIM(Raw_Data!B8),4,2), LEFT(TRIM(Raw_Data!B8),2))), "NA") -> 46127 | C8: CUST-1032 | D8: =IF(OR(LOWER(TRIM(Raw_Data!D8))="north",LOWER(TRIM(Raw_Data!D8))="n.",LOWER(SUBSTITUTE(TRIM(Raw_Data!D8)," ",""))="north"),"North",IF(OR(LOWER(TRIM(Raw_Data!D8))="south",LOWER(TRIM(Raw_Data!D8))="s."),"South",IF(OR(LOWER(TRIM(Raw_Data!D8))="east",LOWER(TRIM(Raw_Data!D8))="e."),"East",IF(OR(LOWER(TRIM(Raw_Data!D8))="west",LOWER(TRIM(Raw_Data!D8))="w."),"West",IF(OR(LOWER(TRIM(Raw_Data!D8))="central",LOWER(TRIM(Raw_Data!D8))="c."),"Central","Unknown"))))) -> East | E8: SKU-1001 | F8: Laptop | G8: Electronics | H8: =IFERROR(VALUE(Raw_Data!H8),0) -> 6 | I8: =IFERROR(VALUE(Raw_Data!I8),0) -> 65000 | J8: =IFERROR(VALUE(Raw_Data!J8),0) -> 0.2 | K8: R002 | L8: =IF(COUNTIF($A$2:A8, A8)>1, "Duplicate", "Valid") -> Valid | M8: =H8*I8*(1-J8) -> 312000 | N8: =IF(COUNTIF($A$2:A8, A8)>1, "Duplicate", IF(OR(B8="NA", ISERROR(B8), ISTEXT(B8)), "Invalid Date", IF(OR(C8=0, E8=0, H8=0, I8=0, J8=0), "Missing Data", "OK"))) -> OK | O8: =IFERROR(INDEX(Reps!$B:$B, MATCH(K8, Reps!$A:$A, 0)), "Not Found") -> Rahul Verma | P8: =IFERROR(TEXT(B8, "mmmm"),"") -> April
A9: ORD-5130 | B9: =IFERROR(IFERROR(INT(VALUE(Raw_Data!B9)), DATE(RIGHT(TRIM(Raw_Data!B9),4), MID(TRIM(Raw_Data!B9),4,2), LEFT(TRIM(Raw_Data!B9),2))), "NA") -> 46036 | C9: CUST-1007 | D9: =IF(OR(LOWER(TRIM(Raw_Data!D9))="north",LOWER(TRIM(Raw_Data!D9))="n.",LOWER(SUBSTITUTE(TRIM(Raw_Data!D9)," ",""))="north"),"North",IF(OR(LOWER(TRIM(Raw_Data!D9))="south",LOWER(TRIM(Raw_Data!D9))="s."),"South",IF(OR(LOWER(TRIM(Raw_Data!D9))="east",LOWER(TRIM(Raw_Data!D9))="e."),"East",IF(OR(LOWER(TRIM(Raw_Data!D9))="west",LOWER(TRIM(Raw_Data!D9))="w."),"West",IF(OR(LOWER(TRIM(Raw_Data!D9))="central",LOWER(TRIM(Raw_Data!D9))="c."),"Central","Unknown"))))) -> North | E9: SKU-1008 | F9: Keyboard | G9: Electronics | H9: =IFERROR(VALUE(Raw_Data!H9),0) -> 12 | I9: =IFERROR(VALUE(Raw_Data!I9),0) -> 3500 | J9: =IFERROR(VALUE(Raw_Data!J9),0) -> 0.1 | K9: R005 | L9: =IF(COUNTIF($A$2:A9, A9)>1, "Duplicate", "Valid") -> Valid | M9: =H9*I9*(1-J9) -> 37800 | N9: =IF(COUNTIF($A$2:A9, A9)>1, "Duplicate", IF(OR(B9="NA", ISERROR(B9), ISTEXT(B9)), "Invalid Date", IF(OR(C9=0, E9=0, H9=0, I9=0, J9=0), "Missing Data", "OK"))) -> OK | O9: =IFERROR(INDEX(Reps!$B:$B, MATCH(K9, Reps!$A:$A, 0)), "Not Found") -> Sneha Reddy | P9: =IFERROR(TEXT(B9, "mmmm"),"") -> January
A10: ORD-5090 | B10: =IFERROR(IFERROR(INT(VALUE(Raw_Data!B10)), DATE(RIGHT(TRIM(Raw_Data!B10),4), MID(TRIM(Raw_Data!B10),4,2), LEFT(TRIM(Raw_Data!B10),2))), "NA") -> 46023 | C10: CUST-1014 | D10: =IF(OR(LOWER(TRIM(Raw_Data!D10))="north",LOWER(TRIM(Raw_Data!D10))="n.",LOWER(SUBSTITUTE(TRIM(Raw_Data!D10)," ",""))="north"),"North",IF(OR(LOWER(TRIM(Raw_Data!D10))="south",LOWER(TRIM(Raw_Data!D10))="s."),"South",IF(OR(LOWER(TRIM(Raw_Data!D10))="east",LOWER(TRIM(Raw_Data!D10))="e."),"East",IF(OR(LOWER(TRIM(Raw_Data!D10))="west",LOWER(TRIM(Raw_Data!D10))="w."),"West",IF(OR(LOWER(TRIM(Raw_Data!D10))="central",LOWER(TRIM(Raw_Data!D10))="c."),"Central","Unknown"))))) -> West | E10: SKU-1001 | F10: Laptop | G10: Electronics | H10: =IFERROR(VALUE(Raw_Data!H10),0) -> 6 | I10: =IFERROR(VALUE(Raw_Data!I10),0) -> 65000 | J10: =IFERROR(VALUE(Raw_Data!J10),0) -> 0.2 | K10: R006 | L10: =IF(COUNTIF($A$2:A10, A10)>1, "Duplicate", "Valid") -> Valid | M10: =H10*I10*(1-J10) -> 312000 | N10: =IF(COUNTIF($A$2:A10, A10)>1, "Duplicate", IF(OR(B10="NA", ISERROR(B10), ISTEXT(B10)), "Invalid Date", IF(OR(C10=0, E10=0, H10=0, I10=0, J10=0), "Missing Data", "OK"))) -> OK | O10: =IFERROR(INDEX(Reps!$B:$B, MATCH(K10, Reps!$A:$A, 0)), "Not Found") -> Vikram Nair | P10: =IFERROR(TEXT(B10, "mmmm"),"") -> January
A11: ORD-5051 | B11: =IFERROR(IFERROR(INT(VALUE(Raw_Data!B11)), DATE(RIGHT(TRIM(Raw_Data!B11),4), MID(TRIM(Raw_Data!B11),4,2), LEFT(TRIM(Raw_Data!B11),2))), "NA") -> 45820 | C11: CUST-1014 | D11: =IF(OR(LOWER(TRIM(Raw_Data!D11))="north",LOWER(TRIM(Raw_Data!D11))="n.",LOWER(SUBSTITUTE(TRIM(Raw_Data!D11)," ",""))="north"),"North",IF(OR(LOWER(TRIM(Raw_Data!D11))="south",LOWER(TRIM(Raw_Data!D11))="s."),"South",IF(OR(LOWER(TRIM(Raw_Data!D11))="east",LOWER(TRIM(Raw_Data!D11))="e."),"East",IF(OR(LOWER(TRIM(Raw_Data!D11))="west",LOWER(TRIM(Raw_Data!D11))="w."),"West",IF(OR(LOWER(TRIM(Raw_Data!D11))="central",LOWER(TRIM(Raw_Data!D11))="c."),"Central","Unknown"))))) -> East | E11: SKU-1003 | F11: Office Chair | G11: Furniture | H11: =IFERROR(VALUE(Raw_Data!H11),0) -> 12 | I11: =IFERROR(VALUE(Raw_Data!I11),0) -> 12000 | J11: =IFERROR(VALUE(Raw_Data!J11),0) -> 0.2 | K11: R004 | L11: =IF(COUNTIF($A$2:A11, A11)>1, "Duplicate", "Valid") -> Valid | M11: =H11*I11*(1-J11) -> 115200 | N11: =IF(COUNTIF($A$2:A11, A11)>1, "Duplicate", IF(OR(B11="NA", ISERROR(B11), ISTEXT(B11)), "Invalid Date", IF(OR(C11=0, E11=0, H11=0, I11=0, J11=0), "Missing Data", "OK"))) -> OK | O11: =IFERROR(INDEX(Reps!$B:$B, MATCH(K11, Reps!$A:$A, 0)), "Not Found") -> Karan Mehta | P11: =IFERROR(TEXT(B11, "mmmm"),"") -> June
A12: ORD-5024 | B12: =IFERROR(IFERROR(INT(VALUE(Raw_Data!B12)), DATE(RIGHT(TRIM(Raw_Data!B12),4), MID(TRIM(Raw_Data!B12),4,2), LEFT(TRIM(Raw_Data!B12),2))), "NA") -> 46010 | C12: CUST-1013 | D12: =IF(OR(LOWER(TRIM(Raw_Data!D12))="north",LOWER(TRIM(Raw_Data!D12))="n.",LOWER(SUBSTITUTE(TRIM(Raw_Data!D12)," ",""))="north"),"North",IF(OR(LOWER(TRIM(Raw_Data!D12))="south",LOWER(TRIM(Raw_Data!D12))="s."),"South",IF(OR(LOWER(TRIM(Raw_Data!D12))="east",LOWER(TRIM(Raw_Data!D12))="e."),"East",IF(OR(LOWER(TRIM(Raw_Data!D12))="west",LOWER(TRIM(Raw_Data!D12))="w."),"West",IF(OR(LOWER(TRIM(Raw_Data!D12))="central",LOWER(TRIM(Raw_Data!D12))="c."),"Central","Unknown"))))) -> North | E12: SKU-1010 | F12: Whiteboard | G12: Office Supplies | H12: =IFERROR(VALUE(Raw_Data!H12),0) -> 12 | I12: =IFERROR(VALUE(Raw_Data!I12),0) -> 2200 | J12: =IFERROR(VALUE(Raw_Data!J12),0) -> 0 | K12: R005 | L12: =IF(COUNTIF($A$2:A12, A12)>1, "Duplicate", "Valid") -> Valid | M12: =H12*I12*(1-J12) -> 26400 | N12: =IF(COUNTIF($A$2:A12, A12)>1, "Duplicate", IF(OR(B12="NA", ISERROR(B12), ISTEXT(B12)), "Invalid Date", IF(OR(C12=0, E12=0, H12=0, I12=0, J12=0), "Missing Data", "OK"))) -> Missing Data | O12: =IFERROR(INDEX(Reps!$B:$B, MATCH(K12, Reps!$A:$A, 0)), "Not Found") -> Sneha Reddy | P12: =IFERROR(TEXT(B12, "mmmm"),"") -> December
A13: ORD-5181 | B13: =IFERROR(IFERROR(INT(VALUE(Raw_Data!B13)), DATE(RIGHT(TRIM(Raw_Data!B13),4), MID(TRIM(Raw_Data!B13),4,2), LEFT(TRIM(Raw_Data!B13),2))), "NA") -> 46014 | C13: CUST-1038 | D13: =IF(OR(LOWER(TRIM(Raw_Data!D13))="north",LOWER(TRIM(Raw_Data!D13))="n.",LOWER(SUBSTITUTE(TRIM(Raw_Data!D13)," ",""))="north"),"North",IF(OR(LOWER(TRIM(Raw_Data!D13))="south",LOWER(TRIM(Raw_Data!D13))="s."),"South",IF(OR(LOWER(TRIM(Raw_Data!D13))="east",LOWER(TRIM(Raw_Data!D13))="e."),"East",IF(OR(LOWER(TRIM(Raw_Data!D13))="west",LOWER(TRIM(Raw_Data!D13))="w."),"West",IF(OR(LOWER(TRIM(Raw_Data!D13))="central",LOWER(TRIM(Raw_Data!D13))="c."),"Central","Unknown"))))) -> North | E13: SKU-1006 | F13: Pen Set | G13: Stationery | H13: =IFERROR(VALUE(Raw_Data!H13),0) -> 12 | I13: =IFERROR(VALUE(Raw_Data!I13),0) -> 450 | J13: =IFERROR(VALUE(Raw_Data!J13),0) -> 0.2 | K13: R002 | L13: =IF(COUNTIF($A$2:A13, A13)>1, "Duplicate", "Valid") -> Valid | M13: =H13*I13*(1-J13) -> 4320 | N13: =IF(COUNTIF($A$2:A13, A13)>1, "Duplicate", IF(OR(B13="NA", ISERROR(B13), ISTEXT(B13)), "Invalid Date", IF(OR(C13=0, E13=0, H13=0, I13=0, J13=0), "Missing Data", "OK"))) -> OK | O13: =IFERROR(INDEX(Reps!$B:$B, MATCH(K13, Reps!$A:$A, 0)), "Not Found") -> Rahul Verma | P13: =IFERROR(TEXT(B13, "mmmm"),"") -> December
... A236: ORD-5180 | B236: =IFERROR(IFERROR(INT(VALUE(Raw_Data!B236)), DATE(RIGHT(TRIM(Raw_Data!B236),4), MID(TRIM(Raw_Data!B236),4,2), LEFT(TRIM(Raw_Data!B236),2))), "NA") -> 46039 | C236: CUST-1015 | D236: =IF(OR(LOWER(TRIM(Raw_Data!D236))="north",LOWER(TRIM(Raw_Data!D236))="n.",LOWER(SUBSTITUTE(TRIM(Raw_Data!D236)," ",""))="north"),"North",IF(OR(LOWER(TRIM(Raw_Data!D236))="south",LOWER(TRIM(Raw_Data!D236))="s."),"South",IF(OR(LOWER(TRIM(Raw_Data!D236))="east",LOWER(TRIM(Raw_Data!D236))="e."),"East",IF(OR(LOWER(TRIM(Raw_Data!D236))="west",LOWER(TRIM(Raw_Data!D236))="w."),"West",IF(OR(LOWER(TRIM(Raw_Data!D236))="central",LOWER(TRIM(Raw_Data!D236))="c."),"Central","Unknown"))))) -> East | E236: SKU-1005 | F236: Notebook | G236: Stationery | H236: =IFERROR(VALUE(Raw_Data!H236),0) -> 8 | I236: =IFERROR(VALUE(Raw_Data!I236),0) -> 250 | J236: =IFERROR(VALUE(Raw_Data!J236),0) -> 0.2 | K236: R004 | L236: =IF(COUNTIF($A$2:A236, A236)>1, "Duplicate", "Valid") -> Valid | M236: =H236*I236*(1-J236) -> 1600 | N236: =IF(COUNTIF($A$2:A236, A236)>1, "Duplicate", IF(OR(B236="NA", ISERROR(B236), ISTEXT(B236)), "Invalid Date", IF(OR(C236=0, E236=0, H236=0, I236=0, J236=0), "Missing Data", "OK"))) -> OK | O236: =IFERROR(INDEX(Reps!$B:$B, MATCH(K236, Reps!$A:$A, 0)), "Not Found") -> Karan Mehta | P236: =IFERROR(TEXT(B236, "mmmm"),"") -> January

Sheet Analysis
A1: Regional Summary | K1: Unique Customers | L1: Revenue by Customer
A2: Region | B2: Total Orders | C2: Total Net Revenue | D2: Average Order Value | E2: Unique Customers | K2: ="CUST-"&TEXT(999+ROWS($K$2:K2),"0000") -> CUST-1000 | L2: =SUMIFS(Cleaned_Data!$M$2:$M$236,Cleaned_Data!$C$2:$C$236,K2,Cleaned_Data!$N$2:$N$236,"OK") -> 440325
A3: West | B3: =COUNTIFS(Cleaned_Data!$D:$D, "West", Cleaned_Data!$N:$N, "OK") -> 25 | C3: =SUMIFS(Cleaned_Data!$M:$M,Cleaned_Data!$D:$D,"West",Cleaned_Data!$N:$N,"OK") -> 3907112.5 | D3: =IFERROR(C3/B3,0) -> 156284.5 | E3: {=SUM(--(FREQUENCY(IF((Cleaned_Data!$D$2:$D$236="West")*(Cleaned_Data!$N$2:$N$236="OK"), MATCH(Cleaned_Data!$C$2:$C$236, Cleaned_Data!$C$2:$C$236, 0)), ROW(Cleaned_Data!$C$2:$C$236)-ROW(Cleaned_Data!$C$2)+1)>0))} -> 21 | K3: ="CUST-"&TEXT(999+ROWS($K$2:K3),"0000") -> CUST-1001 | L3: =SUMIFS(Cleaned_Data!$M$2:$M$236,Cleaned_Data!$C$2:$C$236,K3,Cleaned_Data!$N$2:$N$236,"OK") -> 513950
A4: Central | B4: =COUNTIFS(Cleaned_Data!$D:$D, "Central", Cleaned_Data!$N:$N, "OK") -> 26 | C4: =SUMIFS(Cleaned_Data!$M:$M,Cleaned_Data!$D:$D,"Central",Cleaned_Data!$N:$N,"OK") -> 2588527.5 | D4: =IFERROR(C4/B4,0) -> 99558.75 | E4: {=SUM(--(FREQUENCY(IF((Cleaned_Data!$D$2:$D$236="Central")*(Cleaned_Data!$N$2:$N$236="OK"), MATCH(Cleaned_Data!$C$2:$C$236, Cleaned_Data!$C$2:$C$236, 0)), ROW(Cleaned_Data!$C$2:$C$236)-ROW(Cleaned_Data!$C$2)+1)>0))} -> 17 | K4: ="CUST-"&TEXT(999+ROWS($K$2:K4),"0000") -> CUST-1002 | L4: =SUMIFS(Cleaned_Data!$M$2:$M$236,Cleaned_Data!$C$2:$C$236,K4,Cleaned_Data!$N$2:$N$236,"OK") -> 364000
A5: North | B5: =COUNTIFS(Cleaned_Data!$D:$D, "North", Cleaned_Data!$N:$N, "OK") -> 39 | C5: =SUMIFS(Cleaned_Data!$M:$M,Cleaned_Data!$D:$D,"North",Cleaned_Data!$N:$N,"OK") -> 3182560 | D5: =IFERROR(C5/B5,0) -> 81604.103 | E5: {=SUM(--(FREQUENCY(IF((Cleaned_Data!$D$2:$D$236="North")*(Cleaned_Data!$N$2:$N$236="OK"), MATCH(Cleaned_Data!$C$2:$C$236, Cleaned_Data!$C$2:$C$236, 0)), ROW(Cleaned_Data!$C$2:$C$236)-ROW(Cleaned_Data!$C$2)+1)>0))} -> 26 | K5: ="CUST-"&TEXT(999+ROWS($K$2:K5),"0000") -> CUST-1003 | L5: =SUMIFS(Cleaned_Data!$M$2:$M$236,Cleaned_Data!$C$2:$C$236,K5,Cleaned_Data!$N$2:$N$236,"OK") -> 338190
A6: East | B6: =COUNTIFS(Cleaned_Data!$D:$D, "East", Cleaned_Data!$N:$N, "OK") -> 35 | C6: =SUMIFS(Cleaned_Data!$M:$M,Cleaned_Data!$D:$D,"East",Cleaned_Data!$N:$N,"OK") -> 2467205 | D6: =IFERROR(C6/B6,0) -> 70491.571 | E6: {=SUM(--(FREQUENCY(IF((Cleaned_Data!$D$2:$D$236="East")*(Cleaned_Data!$N$2:$N$236="OK"), MATCH(Cleaned_Data!$C$2:$C$236, Cleaned_Data!$C$2:$C$236, 0)), ROW(Cleaned_Data!$C$2:$C$236)-ROW(Cleaned_Data!$C$2)+1)>0))} -> 23 | K6: ="CUST-"&TEXT(999+ROWS($K$2:K6),"0000") -> CUST-1004 | L6: =SUMIFS(Cleaned_Data!$M$2:$M$236,Cleaned_Data!$C$2:$C$236,K6,Cleaned_Data!$N$2:$N$236,"OK") -> 368400
A7: South | B7: =COUNTIFS(Cleaned_Data!$D:$D, "South", Cleaned_Data!$N:$N, "OK") -> 24 | C7: =SUMIFS(Cleaned_Data!$M:$M,Cleaned_Data!$D:$D,"South",Cleaned_Data!$N:$N,"OK") -> 1990527.5 | D7: =IFERROR(C7/B7,0) -> 82938.646 | E7: {=SUM(--(FREQUENCY(IF((Cleaned_Data!$D$2:$D$236="South")*(Cleaned_Data!$N$2:$N$236="OK"), MATCH(Cleaned_Data!$C$2:$C$236, Cleaned_Data!$C$2:$C$236, 0)), ROW(Cleaned_Data!$C$2:$C$236)-ROW(Cleaned_Data!$C$2)+1)>0))} -> 20 | K7: ="CUST-"&TEXT(999+ROWS($K$2:K7),"0000") -> CUST-1005 | L7: =SUMIFS(Cleaned_Data!$M$2:$M$236,Cleaned_Data!$C$2:$C$236,K7,Cleaned_Data!$N$2:$N$236,"OK") -> 212477.5
K8: ="CUST-"&TEXT(999+ROWS($K$2:K8),"0000") -> CUST-1006 | L8: =SUMIFS(Cleaned_Data!$M$2:$M$236,Cleaned_Data!$C$2:$C$236,K8,Cleaned_Data!$N$2:$N$236,"OK") -> 65625
K9: ="CUST-"&TEXT(999+ROWS($K$2:K9),"0000") -> CUST-1007 | L9: =SUMIFS(Cleaned_Data!$M$2:$M$236,Cleaned_Data!$C$2:$C$236,K9,Cleaned_Data!$N$2:$N$236,"OK") -> 189600
A10: Monthly Revenue Trend | K10: ="CUST-"&TEXT(999+ROWS($K$2:K10),"0000") -> CUST-1008 | L10: =SUMIFS(Cleaned_Data!$M$2:$M$236,Cleaned_Data!$C$2:$C$236,K10,Cleaned_Data!$N$2:$N$236,"OK") -> 770080
A11: Month | B11: Revenue | C11: Delta | D11: Growth % | K11: ="CUST-"&TEXT(999+ROWS($K$2:K11),"0000") -> CUST-1009 | L11: =SUMIFS(Cleaned_Data!$M$2:$M$236,Cleaned_Data!$C$2:$C$236,K11,Cleaned_Data!$N$2:$N$236,"OK") -> 2135
A12: Nov-2025 | B12: =SUMIFS(Cleaned_Data!$M:$M, Cleaned_Data!$B:$B, ">=1/11/2025", Cleaned_Data!$B:$B, "<=30/11/2025", Cleaned_Data!$N:$N, "OK") -> 3190447.5 | K12: ="CUST-"&TEXT(999+ROWS($K$2:K12),"0000") -> CUST-1010 | L12: =SUMIFS(Cleaned_Data!$M$2:$M$236,Cleaned_Data!$C$2:$C$236,K12,Cleaned_Data!$N$2:$N$236,"OK") -> 18150
A13: Dec-2025 | B13: =SUMIFS(Cleaned_Data!$M:$M, Cleaned_Data!$B:$B, ">=1/12/2025", Cleaned_Data!$B:$B, "<=31/12/2025", Cleaned_Data!$N:$N, "OK") -> 1422227.5 | C13: =IFERROR(B13-B12,"") -> -1768220 | D13: =IFERROR(C13/B12,"") -> -0.55422319 | K13: ="CUST-"&TEXT(999+ROWS($K$2:K13),"0000") -> CUST-1011 | L13: =SUMIFS(Cleaned_Data!$M$2:$M$236,Cleaned_Data!$C$2:$C$236,K13,Cleaned_Data!$N$2:$N$236,"OK") -> 0
A14: Jan-2026 | B14: =SUMIFS(Cleaned_Data!$M:$M, Cleaned_Data!$B:$B, ">=1/1/2026", Cleaned_Data!$B:$B, "<=31/1/2026", Cleaned_Data!$N:$N, "OK") -> 1703352.5 | C14: =IFERROR(B14-B13,"") -> 281125 | D14: =IFERROR(C14/B13,"") -> 0.19766528 | K14: ="CUST-"&TEXT(999+ROWS($K$2:K14),"0000") -> CUST-1012 | L14: =SUMIFS(Cleaned_Data!$M$2:$M$236,Cleaned_Data!$C$2:$C$236,K14,Cleaned_Data!$N$2:$N$236,"OK") -> 55100
A15: Feb-2026 | B15: =SUMIFS(Cleaned_Data!$M:$M, Cleaned_Data!$B:$B, ">=1/2/2026", Cleaned_Data!$B:$B, "<=28/2/2026", Cleaned_Data!$N:$N, "OK") -> 1460880 | C15: =IFERROR(B15-B14,"") -> -242472.5 | D15: =IFERROR(C15/B14,"") -> -0.14235016 | K15: ="CUST-"&TEXT(999+ROWS($K$2:K15),"0000") -> CUST-1013 | L15: =SUMIFS(Cleaned_Data!$M$2:$M$236,Cleaned_Data!$C$2:$C$236,K15,Cleaned_Data!$N$2:$N$236,"OK") -> 185625
A16: Mar-2026 | B16: =SUMIFS(Cleaned_Data!$M:$M, Cleaned_Data!$B:$B, ">=1/3/2026", Cleaned_Data!$B:$B, "<=31/3/2026", Cleaned_Data!$N:$N, "OK") -> 1901385 | C16: =IFERROR(B16-B15,"") -> 440505 | D16: =IFERROR(C16/B15,"") -> 0.30153401 | K16: ="CUST-"&TEXT(999+ROWS($K$2:K16),"0000") -> CUST-1014 | L16: =SUMIFS(Cleaned_Data!$M$2:$M$236,Cleaned_Data!$C$2:$C$236,K16,Cleaned_Data!$N$2:$N$236,"OK") -> 1044850
A17: Apr-2026 | B17: =SUMIFS(Cleaned_Data!$M:$M, Cleaned_Data!$B:$B, ">=1/4/2026", Cleaned_Data!$B:$B, "<=30/4/2026", Cleaned_Data!$N:$N, "OK") -> 3630122.5 | C17: =IFERROR(B17-B16,"") -> 1728737.5 | D17: =IFERROR(C17/B16,"") -> 0.90919908 | K17: ="CUST-"&TEXT(999+ROWS($K$2:K17),"0000") -> CUST-1015 | L17: =SUMIFS(Cleaned_Data!$M$2:$M$236,Cleaned_Data!$C$2:$C$236,K17,Cleaned_Data!$N$2:$N$236,"OK") -> 1339662.5
K18: ="CUST-"&TEXT(999+ROWS($K$2:K18),"0000") -> CUST-1016 | L18: =SUMIFS(Cleaned_Data!$M$2:$M$236,Cleaned_Data!$C$2:$C$236,K18,Cleaned_Data!$N$2:$N$236,"OK") -> 336930
K19: ="CUST-"&TEXT(999+ROWS($K$2:K19),"0000") -> CUST-1017 | L19: =SUMIFS(Cleaned_Data!$M$2:$M$236,Cleaned_Data!$C$2:$C$236,K19,Cleaned_Data!$N$2:$N$236,"OK") -> 352210
A20: Achievement % | K20: ="CUST-"&TEXT(999+ROWS($K$2:K20),"0000") -> CUST-1018 | L20: =SUMIFS(Cleaned_Data!$M$2:$M$236,Cleaned_Data!$C$2:$C$236,K20,Cleaned_Data!$N$2:$N$236,"OK") -> 370450
B21: Nov-2025 | C21: Dec-2025 | D21: Jan-2026 | E21: Feb-2026 | F21: Mar-2026 | G21: Apr-2026 | K21: ="CUST-"&TEXT(999+ROWS($K$2:K21),"0000") -> CUST-1019 | L21: =SUMIFS(Cleaned_Data!$M$2:$M$236,Cleaned_Data!$C$2:$C$236,K21,Cleaned_Data!$N$2:$N$236,"OK") -> 985400
A22: North | B22: =IFERROR(SUMIFS(Cleaned_Data!$M:$M, Cleaned_Data!$D:$D, $A22, Cleaned_Data!$B:$B, ">="&B$21, Cleaned_Data!$B:$B, "<="&EOMONTH(B$21, 0), Cleaned_Data!$N:$N, "OK") / INDEX(Targets!$B$2:$G$6, MATCH($A22, Targets!$A$2:$A$6, 0), MATCH(B$21, Targets!$B$1:$G$1, 0)), 0) -> 0.79773529 | C22: =IFERROR(SUMIFS(Cleaned_Data!$M:$M, Cleaned_Data!$D:$D, $A22, Cleaned_Data!$B:$B, ">="&C$21, Cleaned_Data!$B:$B, "<="&EOMONTH(C$21, 0), Cleaned_Data!$N:$N, "OK") / INDEX(Targets!$B$2:$G$6, MATCH($A22, Targets!$A$2:$A$6, 0), MATCH(C$21, Targets!$B$1:$G$1, 0)), 0) -> 0.38902222 | D22: =IFERROR(SUMIFS(Cleaned_Data!$M:$M, Cleaned_Data!$D:$D, $A22, Cleaned_Data!$B:$B, ">="&D$21, Cleaned_Data!$B:$B, "<="&EOMONTH(D$21, 0), Cleaned_Data!$N:$N, "OK") / INDEX(Targets!$B$2:$G$6, MATCH($A22, Targets!$A$2:$A$6, 0), MATCH(D$21, Targets!$B$1:$G$1, 0)), 0) -> 0.092032609 | E22: =IFERROR(SUMIFS(Cleaned_Data!$M:$M, Cleaned_Data!$D:$D, $A22, Cleaned_Data!$B:$B, ">="&E$21, Cleaned_Data!$B:$B, "<="&EOMONTH(E$21, 0), Cleaned_Data!$N:$N, "OK") / INDEX(Targets!$B$2:$G$6, MATCH($A22, Targets!$A$2:$A$6, 0), MATCH(E$21, Targets!$B$1:$G$1, 0)), 0) -> 0.1333267 | F22: =IFERROR(SUMIFS(Cleaned_Data!$M:$M, Cleaned_Data!$D:$D, $A22, Cleaned_Data!$B:$B, ">="&F$21, Cleaned_Data!$B:$B, "<="&EOMONTH(F$21, 0), Cleaned_Data!$N:$N, "OK") / INDEX(Targets!$B$2:$G$6, MATCH($A22, Targets!$A$2:$A$6, 0), MATCH(F$21, Targets!$B$1:$G$1, 0)), 0) -> 0.053357895 | G22: =IFERROR(SUMIFS(Cleaned_Data!$M:$M, Cleaned_Data!$D:$D, $A22, Cleaned_Data!$B:$B, ">="&G$21, Cleaned_Data!$B:$B, "<="&EOMONTH(G$21, 0), Cleaned_Data!$N:$N, "OK") / INDEX(Targets!$B$2:$G$6, MATCH($A22, Targets!$A$2:$A$6, 0), MATCH(G$21, Targets!$B$1:$G$1, 0)), 0) -> 1.59531 | K22: ="CUST-"&TEXT(999+ROWS($K$2:K22),"0000") -> CUST-1020 | L22: =SUMIFS(Cleaned_Data!$M$2:$M$236,Cleaned_Data!$C$2:$C$236,K22,Cleaned_Data!$N$2:$N$236,"OK") -> 94050
A23: South | B23: =IFERROR(SUMIFS(Cleaned_Data!$M:$M, Cleaned_Data!$D:$D, $A23, Cleaned_Data!$B:$B, ">="&B$21, Cleaned_Data!$B:$B, "<="&EOMONTH(B$21, 0), Cleaned_Data!$N:$N, "OK") / INDEX(Targets!$B$2:$G$6, MATCH($A23, Targets!$A$2:$A$6, 0), MATCH(B$21, Targets!$B$1:$G$1, 0)), 0) -> 0.21358333 | C23: =IFERROR(SUMIFS(Cleaned_Data!$M:$M, Cleaned_Data!$D:$D, $A23, Cleaned_Data!$B:$B, ">="&C$21, Cleaned_Data!$B:$B, "<="&EOMONTH(C$21, 0), Cleaned_Data!$N:$N, "OK") / INDEX(Targets!$B$2:$G$6, MATCH($A23, Targets!$A$2:$A$6, 0), MATCH(C$21, Targets!$B$1:$G$1, 0)), 0) -> 0.097335366 | D23: =IFERROR(SUMIFS(Cleaned_Data!$M:$M, Cleaned_Data!$D:$D, $A23, Cleaned_Data!$B:$B, ">="&D$21, Cleaned_Data!$B:$B, "<="&EOMONTH(D$21, 0), Cleaned_Data!$N:$N, "OK") / INDEX(Targets!$B$2:$G$6, MATCH($A23, Targets!$A$2:$A$6, 0), MATCH(D$21, Targets!$B$1:$G$1, 0)), 0) -> 0.82583235 | E23: =IFERROR(SUMIFS(Cleaned_Data!$M:$M, Cleaned_Data!$D:$D, $A23, Cleaned_Data!$B:$B, ">="&E$21, Cleaned_Data!$B:$B, "<="&EOMONTH(E$21, 0), Cleaned_Data!$N:$N, "OK") / INDEX(Targets!$B$2:$G$6, MATCH($A23, Targets!$A$2:$A$6, 0), MATCH(E$21, Targets!$B$1:$G$1, 0)), 0) -> 0.02109375 | F23: =IFERROR(SUMIFS(Cleaned_Data!$M:$M, Cleaned_Data!$D:$D, $A23, Cleaned_Data!$B:$B, ">="&F$21, Cleaned_Data!$B:$B, "<="&EOMONTH(F$21, 0), Cleaned_Data!$N:$N, "OK") / INDEX(Targets!$B$2:$G$6, MATCH($A23, Targets!$A$2:$A$6, 0), MATCH(F$21, Targets!$B$1:$G$1, 0)), 0) -> 0.42023864 | G23: =IFERROR(SUMIFS(Cleaned_Data!$M:$M, Cleaned_Data!$D:$D, $A23, Cleaned_Data!$B:$B, ">="&G$21, Cleaned_Data!$B:$B, "<="&EOMONTH(G$21, 0), Cleaned_Data!$N:$N, "OK") / INDEX(Targets!$B$2:$G$6, MATCH($A23, Targets!$A$2:$A$6, 0), MATCH(G$21, Targets!$B$1:$G$1, 0)), 0) -> 0.48652174 | K23: ="CUST-"&TEXT(999+ROWS($K$2:K23),"0000") -> CUST-1021 | L23: =SUMIFS(Cleaned_Data!$M$2:$M$236,Cleaned_Data!$C$2:$C$236,K23,Cleaned_Data!$N$2:$N$236,"OK") -> 71995
A24: East | B24: =IFERROR(SUMIFS(Cleaned_Data!$M:$M, Cleaned_Data!$D:$D, $A24, Cleaned_Data!$B:$B, ">="&B$21, Cleaned_Data!$B:$B, "<="&EOMONTH(B$21, 0), Cleaned_Data!$N:$N, "OK") / INDEX(Targets!$B$2:$G$6, MATCH($A24, Targets!$A$2:$A$6, 0), MATCH(B$21, Targets!$B$1:$G$1, 0)), 0) -> 1.0665645 | C24: =IFERROR(SUMIFS(Cleaned_Data!$M:$M, Cleaned_Data!$D:$D, $A24, Cleaned_Data!$B:$B, ">="&C$21, Cleaned_Data!$B:$B, "<="&EOMONTH(C$21, 0), Cleaned_Data!$N:$N, "OK") / INDEX(Targets!$B$2:$G$6, MATCH($A24, Targets!$A$2:$A$6, 0), MATCH(C$21, Targets!$B$1:$G$1, 0)), 0) -> 0.0040846154 | D24: =IFERROR(SUMIFS(Cleaned_Data!$M:$M, Cleaned_Data!$D:$D, $A24, Cleaned_Data!$B:$B, ">="&D$21, Cleaned_Data!$B:$B, "<="&EOMONTH(D$21, 0), Cleaned_Data!$N:$N, "OK") / INDEX(Targets!$B$2:$G$6, MATCH($A24, Targets!$A$2:$A$6, 0), MATCH(D$21, Targets!$B$1:$G$1, 0)), 0) -> 0.19919118 | E24: =IFERROR(SUMIFS(Cleaned_Data!$M:$M, Cleaned_Data!$D:$D, $A24, Cleaned_Data!$B:$B, ">="&E$21, Cleaned_Data!$B:$B, "<="&EOMONTH(E$21, 0), Cleaned_Data!$N:$N, "OK") / INDEX(Targets!$B$2:$G$6, MATCH($A24, Targets!$A$2:$A$6, 0), MATCH(E$21, Targets!$B$1:$G$1, 0)), 0) -> 0.82293939 | F24: =IFERROR(SUMIFS(Cleaned_Data!$M:$M, Cleaned_Data!$D:$D, $A24, Cleaned_Data!$B:$B, ">="&F$21, Cleaned_Data!$B:$B, "<="&EOMONTH(F$21, 0), Cleaned_Data!$N:$N, "OK") / INDEX(Targets!$B$2:$G$6, MATCH($A24, Targets!$A$2:$A$6, 0), MATCH(F$21, Targets!$B$1:$G$1, 0)), 0) -> 0.44512143 | G24: =IFERROR(SUMIFS(Cleaned_Data!$M:$M, Cleaned_Data!$D:$D, $A24, Cleaned_Data!$B:$B, ">="&G$21, Cleaned_Data!$B:$B, "<="&EOMONTH(G$21, 0), Cleaned_Data!$N:$N, "OK") / INDEX(Targets!$B$2:$G$6, MATCH($A24, Targets!$A$2:$A$6, 0), MATCH(G$21, Targets!$B$1:$G$1, 0)), 0) -> 0.79240541 | K24: ="CUST-"&TEXT(999+ROWS($K$2:K24),"0000") -> CUST-1022 | L24: =SUMIFS(Cleaned_Data!$M$2:$M$236,Cleaned_Data!$C$2:$C$236,K24,Cleaned_Data!$N$2:$N$236,"OK") -> 940200
A25: West | B25: =IFERROR(SUMIFS(Cleaned_Data!$M:$M, Cleaned_Data!$D:$D, $A25, Cleaned_Data!$B:$B, ">="&B$21, Cleaned_Data!$B:$B, "<="&EOMONTH(B$21, 0), Cleaned_Data!$N:$N, "OK") / INDEX(Targets!$B$2:$G$6, MATCH($A25, Targets!$A$2:$A$6, 0), MATCH(B$21, Targets!$B$1:$G$1, 0)), 0) -> 0.89107143 | C25: =IFERROR(SUMIFS(Cleaned_Data!$M:$M, Cleaned_Data!$D:$D, $A25, Cleaned_Data!$B:$B, ">="&C$21, Cleaned_Data!$B:$B, "<="&EOMONTH(C$21, 0), Cleaned_Data!$N:$N, "OK") / INDEX(Targets!$B$2:$G$6, MATCH($A25, Targets!$A$2:$A$6, 0), MATCH(C$21, Targets!$B$1:$G$1, 0)), 0) -> 0.83758562 | D25: =IFERROR(SUMIFS(Cleaned_Data!$M:$M, Cleaned_Data!$D:$D, $A25, Cleaned_Data!$B:$B, ">="&D$21, Cleaned_Data!$B:$B, "<="&EOMONTH(D$21, 0), Cleaned_Data!$N:$N, "OK") / INDEX(Targets!$B$2:$G$6, MATCH($A25, Targets!$A$2:$A$6, 0), MATCH(D$21, Targets!$B$1:$G$1, 0)), 0) -> 0.53641447 | E25: =IFERROR(SUMIFS(Cleaned_Data!$M:$M, Cleaned_Data!$D:$D, $A25, Cleaned_Data!$B:$B, ">="&E$21, Cleaned_Data!$B:$B, "<="&EOMONTH(E$21, 0), Cleaned_Data!$N:$N, "OK") / INDEX(Targets!$B$2:$G$6, MATCH($A25, Targets!$A$2:$A$6, 0), MATCH(E$21, Targets!$B$1:$G$1, 0)), 0) -> 0.68436149 | F25: =IFERROR(SUMIFS(Cleaned_Data!$M:$M, Cleaned_Data!$D:$D, $A25, Cleaned_Data!$B:$B, ">="&F$21, Cleaned_Data!$B:$B, "<="&EOMONTH(F$21, 0), Cleaned_Data!$N:$N, "OK") / INDEX(Targets!$B$2:$G$6, MATCH($A25, Targets!$A$2:$A$6, 0), MATCH(F$21, Targets!$B$1:$G$1, 0)), 0) -> 0.9971519 | G25: =IFERROR(SUMIFS(Cleaned_Data!$M:$M, Cleaned_Data!$D:$D, $A25, Cleaned_Data!$B:$B, ">="&G$21, Cleaned_Data!$B:$B, "<="&EOMONTH(G$21, 0), Cleaned_Data!$N:$N, "OK") / INDEX(Targets!$B$2:$G$6, MATCH($A25, Targets!$A$2:$A$6, 0), MATCH(G$21, Targets!$B$1:$G$1, 0)), 0) -> 0.88738855 | K25: ="CUST-"&TEXT(999+ROWS($K$2:K25),"0000") -> CUST-1023 | L25: =SUMIFS(Cleaned_Data!$M$2:$M$236,Cleaned_Data!$C$2:$C$236,K25,Cleaned_Data!$N$2:$N$236,"OK") -> 105150
A26: Central | B26: =IFERROR(SUMIFS(Cleaned_Data!$M:$M, Cleaned_Data!$D:$D, $A26, Cleaned_Data!$B:$B, ">="&B$21, Cleaned_Data!$B:$B, "<="&EOMONTH(B$21, 0), Cleaned_Data!$N:$N, "OK") / INDEX(Targets!$B$2:$G$6, MATCH($A26, Targets!$A$2:$A$6, 0), MATCH(B$21, Targets!$B$1:$G$1, 0)), 0) -> 1.949412 | C26: =IFERROR(SUMIFS(Cleaned_Data!$M:$M, Cleaned_Data!$D:$D, $A26, Cleaned_Data!$B:$B, ">="&C$21, Cleaned_Data!$B:$B, "<="&EOMONTH(C$21, 0), Cleaned_Data!$N:$N, "OK") / INDEX(Targets!$B$2:$G$6, MATCH($A26, Targets!$A$2:$A$6, 0), MATCH(C$21, Targets!$B$1:$G$1, 0)), 0) -> 0.37403509 | D26: =IFERROR(SUMIFS(Cleaned_Data!$M:$M, Cleaned_Data!$D:$D, $A26, Cleaned_Data!$B:$B, ">="&D$21, Cleaned_Data!$B:$B, "<="&EOMONTH(D$21, 0), Cleaned_Data!$N:$N, "OK") / INDEX(Targets!$B$2:$G$6, MATCH($A26, Targets!$A$2:$A$6, 0), MATCH(D$21, Targets!$B$1:$G$1, 0)), 0) -> 0.62266667 | E26: =IFERROR(SUMIFS(Cleaned_Data!$M:$M, Cleaned_Data!$D:$D, $A26, Cleaned_Data!$B:$B, ">="&E$21, Cleaned_Data!$B:$B, "<="&EOMONTH(E$21, 0), Cleaned_Data!$N:$N, "OK") / INDEX(Targets!$B$2:$G$6, MATCH($A26, Targets!$A$2:$A$6, 0), MATCH(E$21, Targets!$B$1:$G$1, 0)), 0) -> 0.45615517 | F26: =IFERROR(SUMIFS(Cleaned_Data!$M:$M, Cleaned_Data!$D:$D, $A26, Cleaned_Data!$B:$B, ">="&F$21, Cleaned_Data!$B:$B, "<="&EOMONTH(F$21, 0), Cleaned_Data!$N:$N, "OK") / INDEX(Targets!$B$2:$G$6, MATCH($A26, Targets!$A$2:$A$6, 0), MATCH(F$21, Targets!$B$1:$G$1, 0)), 0) -> 0.46298387 | G26: =IFERROR(SUMIFS(Cleaned_Data!$M:$M, Cleaned_Data!$D:$D, $A26, Cleaned_Data!$B:$B, ">="&G$21, Cleaned_Data!$B:$B, "<="&EOMONTH(G$21, 0), Cleaned_Data!$N:$N, "OK") / INDEX(Targets!$B$2:$G$6, MATCH($A26, Targets!$A$2:$A$6, 0), MATCH(G$21, Targets!$B$1:$G$1, 0)), 0) -> 0.40045455 | K26: ="CUST-"&TEXT(999+ROWS($K$2:K26),"0000") -> CUST-1024 | L26: =SUMIFS(Cleaned_Data!$M$2:$M$236,Cleaned_Data!$C$2:$C$236,K26,Cleaned_Data!$N$2:$N$236,"OK") -> 609775
K27: ="CUST-"&TEXT(999+ROWS($K$2:K27),"0000") -> CUST-1025 | L27: =SUMIFS(Cleaned_Data!$M$2:$M$236,Cleaned_Data!$C$2:$C$236,K27,Cleaned_Data!$N$2:$N$236,"OK") -> 414962.5
K28: ="CUST-"&TEXT(999+ROWS($K$2:K28),"0000") -> CUST-1026 | L28: =SUMIFS(Cleaned_Data!$M$2:$M$236,Cleaned_Data!$C$2:$C$236,K28,Cleaned_Data!$N$2:$N$236,"OK") -> 470362.5
A29: Top 5 Customers | K29: ="CUST-"&TEXT(999+ROWS($K$2:K29),"0000") -> CUST-1027 | L29: =SUMIFS(Cleaned_Data!$M$2:$M$236,Cleaned_Data!$C$2:$C$236,K29,Cleaned_Data!$N$2:$N$236,"OK") -> 655425
A30: Customer | B30: Revenue | K30: ="CUST-"&TEXT(999+ROWS($K$2:K30),"0000") -> CUST-1028 | L30: =SUMIFS(Cleaned_Data!$M$2:$M$236,Cleaned_Data!$C$2:$C$236,K30,Cleaned_Data!$N$2:$N$236,"OK") -> 116697.5
A31: =INDEX($K2:$K$50,MATCH(LARGE($L$2:$L$50,1),$L$2:$L$50,0)) -> CUST-1015 | B31: =LARGE($L$2:$L$50,1) -> 1339662.5 | K31: ="CUST-"&TEXT(999+ROWS($K$2:K31),"0000") -> CUST-1029 | L31: =SUMIFS(Cleaned_Data!$M$2:$M$236,Cleaned_Data!$C$2:$C$236,K31,Cleaned_Data!$N$2:$N$236,"OK") -> 411595
A32: =INDEX($K2:$K$50,MATCH(LARGE($L$2:$L$50,2),$L$2:$L$50,0)) -> CUST-1014 | B32: =LARGE($L$2:$L$50,2) -> 1044850 | K32: ="CUST-"&TEXT(999+ROWS($K$2:K32),"0000") -> CUST-1030 | L32: =SUMIFS(Cleaned_Data!$M$2:$M$236,Cleaned_Data!$C$2:$C$236,K32,Cleaned_Data!$N$2:$N$236,"OK") -> 299532.5
A33: =INDEX($K2:$K$50,MATCH(LARGE($L$2:$L$50,3),$L$2:$L$50,0)) -> CUST-1019 | B33: =LARGE($L$2:$L$50,3) -> 985400 | K33: ="CUST-"&TEXT(999+ROWS($K$2:K33),"0000") -> CUST-1031 | L33: =SUMIFS(Cleaned_Data!$M$2:$M$236,Cleaned_Data!$C$2:$C$236,K33,Cleaned_Data!$N$2:$N$236,"OK") -> 122840
A34: =INDEX($K2:$K$50,MATCH(LARGE($L$2:$L$50,4),$L$2:$L$50,0)) -> CUST-1022 | B34: =LARGE($L$2:$L$50,4) -> 940200 | K34: ="CUST-"&TEXT(999+ROWS($K$2:K34),"0000") -> CUST-1032 | L34: =SUMIFS(Cleaned_Data!$M$2:$M$236,Cleaned_Data!$C$2:$C$236,K34,Cleaned_Data!$N$2:$N$236,"OK") -> 808475
A35: =INDEX($K2:$K$50,MATCH(LARGE($L$2:$L$50,5),$L$2:$L$50,0)) -> CUST-1032 | B35: =LARGE($L$2:$L$50,5) -> 808475 | K35: ="CUST-"&TEXT(999+ROWS($K$2:K35),"0000") -> CUST-1033 | L35: =SUMIFS(Cleaned_Data!$M$2:$M$236,Cleaned_Data!$C$2:$C$236,K35,Cleaned_Data!$N$2:$N$236,"OK") -> 102600
K36: ="CUST-"&TEXT(999+ROWS($K$2:K36),"0000") -> CUST-1034 | L36: =SUMIFS(Cleaned_Data!$M$2:$M$236,Cleaned_Data!$C$2:$C$236,K36,Cleaned_Data!$N$2:$N$236,"OK") -> 275025
K37: ="CUST-"&TEXT(999+ROWS($K$2:K37),"0000") -> CUST-1035 | L37: =SUMIFS(Cleaned_Data!$M$2:$M$236,Cleaned_Data!$C$2:$C$236,K37,Cleaned_Data!$N$2:$N$236,"OK") -> 355420
K38: ="CUST-"&TEXT(999+ROWS($K$2:K38),"0000") -> CUST-1036 | L38: =SUMIFS(Cleaned_Data!$M$2:$M$236,Cleaned_Data!$C$2:$C$236,K38,Cleaned_Data!$N$2:$N$236,"OK") -> 141225
K39: ="CUST-"&TEXT(999+ROWS($K$2:K39),"0000") -> CUST-1037 | L39: =SUMIFS(Cleaned_Data!$M$2:$M$236,Cleaned_Data!$C$2:$C$236,K39,Cleaned_Data!$N$2:$N$236,"OK") -> 806210
K40: ="CUST-"&TEXT(999+ROWS($K$2:K40),"0000") -> CUST-1038 | L40: =SUMIFS(Cleaned_Data!$M$2:$M$236,Cleaned_Data!$C$2:$C$236,K40,Cleaned_Data!$N$2:$N$236,"OK") -> 180022.5
...

Sheet Pivot false
A1: Revenue Pivot - Net Revenue by Region and Month
A2: Region | B2: Nov-2025 | C2: Dec-2025 | D2: Jan-2026 | E2: Feb-2026 | F2: Mar-2026 | G2: Apr-2026
A3: North | B3: =SUMIFS(Cleaned_Data!$M$2:$M$236,Cleaned_Data!$D$2:$D$236,$A3,Cleaned_Data!$B$2:$B$236,">="&B$2,Cleaned_Data!$B$2:$B$236,"<="&EOMONTH(B$2,0),Cleaned_Data!$N$2:$N$236,"OK") -> 678075 | C3: =SUMIFS(Cleaned_Data!$M$2:$M$236,Cleaned_Data!$D$2:$D$236,$A3,Cleaned_Data!$B$2:$B$236,">="&C$2,Cleaned_Data!$B$2:$B$236,"<="&EOMONTH(C$2,0),Cleaned_Data!$N$2:$N$236,"OK") -> 350120 | D3: =SUMIFS(Cleaned_Data!$M$2:$M$236,Cleaned_Data!$D$2:$D$236,$A3,Cleaned_Data!$B$2:$B$236,">="&D$2,Cleaned_Data!$B$2:$B$236,"<="&EOMONTH(D$2,0),Cleaned_Data!$N$2:$N$236,"OK") -> 84670 | E3: =SUMIFS(Cleaned_Data!$M$2:$M$236,Cleaned_Data!$D$2:$D$236,$A3,Cleaned_Data!$B$2:$B$236,">="&E$2,Cleaned_Data!$B$2:$B$236,"<="&EOMONTH(E$2,0),Cleaned_Data!$N$2:$N$236,"OK") -> 117327.5 | F3: =SUMIFS(Cleaned_Data!$M$2:$M$236,Cleaned_Data!$D$2:$D$236,$A3,Cleaned_Data!$B$2:$B$236,">="&F$2,Cleaned_Data!$B$2:$B$236,"<="&EOMONTH(F$2,0),Cleaned_Data!$N$2:$N$236,"OK") -> 50690 | G3: =SUMIFS(Cleaned_Data!$M$2:$M$236,Cleaned_Data!$D$2:$D$236,$A3,Cleaned_Data!$B$2:$B$236,">="&G$2,Cleaned_Data!$B$2:$B$236,"<="&EOMONTH(G$2,0),Cleaned_Data!$N$2:$N$236,"OK") -> 1595310
A4: South | B4: =SUMIFS(Cleaned_Data!$M$2:$M$236,Cleaned_Data!$D$2:$D$236,$A4,Cleaned_Data!$B$2:$B$236,">="&B$2,Cleaned_Data!$B$2:$B$236,"<="&EOMONTH(B$2,0),Cleaned_Data!$N$2:$N$236,"OK") -> 166595 | C4: =SUMIFS(Cleaned_Data!$M$2:$M$236,Cleaned_Data!$D$2:$D$236,$A4,Cleaned_Data!$B$2:$B$236,">="&C$2,Cleaned_Data!$B$2:$B$236,"<="&EOMONTH(C$2,0),Cleaned_Data!$N$2:$N$236,"OK") -> 79815 | D4: =SUMIFS(Cleaned_Data!$M$2:$M$236,Cleaned_Data!$D$2:$D$236,$A4,Cleaned_Data!$B$2:$B$236,">="&D$2,Cleaned_Data!$B$2:$B$236,"<="&EOMONTH(D$2,0),Cleaned_Data!$N$2:$N$236,"OK") -> 701957.5 | E4: =SUMIFS(Cleaned_Data!$M$2:$M$236,Cleaned_Data!$D$2:$D$236,$A4,Cleaned_Data!$B$2:$B$236,">="&E$2,Cleaned_Data!$B$2:$B$236,"<="&EOMONTH(E$2,0),Cleaned_Data!$N$2:$N$236,"OK") -> 16875 | F4: =SUMIFS(Cleaned_Data!$M$2:$M$236,Cleaned_Data!$D$2:$D$236,$A4,Cleaned_Data!$B$2:$B$236,">="&F$2,Cleaned_Data!$B$2:$B$236,"<="&EOMONTH(F$2,0),Cleaned_Data!$N$2:$N$236,"OK") -> 369810 | G4: =SUMIFS(Cleaned_Data!$M$2:$M$236,Cleaned_Data!$D$2:$D$236,$A4,Cleaned_Data!$B$2:$B$236,">="&G$2,Cleaned_Data!$B$2:$B$236,"<="&EOMONTH(G$2,0),Cleaned_Data!$N$2:$N$236,"OK") -> 447600
A5: East | B5: =SUMIFS(Cleaned_Data!$M$2:$M$236,Cleaned_Data!$D$2:$D$236,$A5,Cleaned_Data!$B$2:$B$236,">="&B$2,Cleaned_Data!$B$2:$B$236,"<="&EOMONTH(B$2,0),Cleaned_Data!$N$2:$N$236,"OK") -> 661270 | C5: =SUMIFS(Cleaned_Data!$M$2:$M$236,Cleaned_Data!$D$2:$D$236,$A5,Cleaned_Data!$B$2:$B$236,">="&C$2,Cleaned_Data!$B$2:$B$236,"<="&EOMONTH(C$2,0),Cleaned_Data!$N$2:$N$236,"OK") -> 2655 | D5: =SUMIFS(Cleaned_Data!$M$2:$M$236,Cleaned_Data!$D$2:$D$236,$A5,Cleaned_Data!$B$2:$B$236,">="&D$2,Cleaned_Data!$B$2:$B$236,"<="&EOMONTH(D$2,0),Cleaned_Data!$N$2:$N$236,"OK") -> 135450 | E5: =SUMIFS(Cleaned_Data!$M$2:$M$236,Cleaned_Data!$D$2:$D$236,$A5,Cleaned_Data!$B$2:$B$236,">="&E$2,Cleaned_Data!$B$2:$B$236,"<="&EOMONTH(E$2,0),Cleaned_Data!$N$2:$N$236,"OK") -> 543140 | F5: =SUMIFS(Cleaned_Data!$M$2:$M$236,Cleaned_Data!$D$2:$D$236,$A5,Cleaned_Data!$B$2:$B$236,">="&F$2,Cleaned_Data!$B$2:$B$236,"<="&EOMONTH(F$2,0),Cleaned_Data!$N$2:$N$236,"OK") -> 311585 | G5: =SUMIFS(Cleaned_Data!$M$2:$M$236,Cleaned_Data!$D$2:$D$236,$A5,Cleaned_Data!$B$2:$B$236,">="&G$2,Cleaned_Data!$B$2:$B$236,"<="&EOMONTH(G$2,0),Cleaned_Data!$N$2:$N$236,"OK") -> 586380
A6: West | B6: =SUMIFS(Cleaned_Data!$M$2:$M$236,Cleaned_Data!$D$2:$D$236,$A6,Cleaned_Data!$B$2:$B$236,">="&B$2,Cleaned_Data!$B$2:$B$236,"<="&EOMONTH(B$2,0),Cleaned_Data!$N$2:$N$236,"OK") -> 623750 | C6: =SUMIFS(Cleaned_Data!$M$2:$M$236,Cleaned_Data!$D$2:$D$236,$A6,Cleaned_Data!$B$2:$B$236,">="&C$2,Cleaned_Data!$B$2:$B$236,"<="&EOMONTH(C$2,0),Cleaned_Data!$N$2:$N$236,"OK") -> 611437.5 | D6: =SUMIFS(Cleaned_Data!$M$2:$M$236,Cleaned_Data!$D$2:$D$236,$A6,Cleaned_Data!$B$2:$B$236,">="&D$2,Cleaned_Data!$B$2:$B$236,"<="&EOMONTH(D$2,0),Cleaned_Data!$N$2:$N$236,"OK") -> 407675 | E6: =SUMIFS(Cleaned_Data!$M$2:$M$236,Cleaned_Data!$D$2:$D$236,$A6,Cleaned_Data!$B$2:$B$236,">="&E$2,Cleaned_Data!$B$2:$B$236,"<="&EOMONTH(E$2,0),Cleaned_Data!$N$2:$N$236,"OK") -> 506427.5 | F6: =SUMIFS(Cleaned_Data!$M$2:$M$236,Cleaned_Data!$D$2:$D$236,$A6,Cleaned_Data!$B$2:$B$236,">="&F$2,Cleaned_Data!$B$2:$B$236,"<="&EOMONTH(F$2,0),Cleaned_Data!$N$2:$N$236,"OK") -> 787750 | G6: =SUMIFS(Cleaned_Data!$M$2:$M$236,Cleaned_Data!$D$2:$D$236,$A6,Cleaned_Data!$B$2:$B$236,">="&G$2,Cleaned_Data!$B$2:$B$236,"<="&EOMONTH(G$2,0),Cleaned_Data!$N$2:$N$236,"OK") -> 736532.5
A7: Central | B7: =SUMIFS(Cleaned_Data!$M$2:$M$236,Cleaned_Data!$D$2:$D$236,$A7,Cleaned_Data!$B$2:$B$236,">="&B$2,Cleaned_Data!$B$2:$B$236,"<="&EOMONTH(B$2,0),Cleaned_Data!$N$2:$N$236,"OK") -> 1052682.5 | C7: =SUMIFS(Cleaned_Data!$M$2:$M$236,Cleaned_Data!$D$2:$D$236,$A7,Cleaned_Data!$B$2:$B$236,">="&C$2,Cleaned_Data!$B$2:$B$236,"<="&EOMONTH(C$2,0),Cleaned_Data!$N$2:$N$236,"OK") -> 213200 | D7: =SUMIFS(Cleaned_Data!$M$2:$M$236,Cleaned_Data!$D$2:$D$236,$A7,Cleaned_Data!$B$2:$B$236,">="&D$2,Cleaned_Data!$B$2:$B$236,"<="&EOMONTH(D$2,0),Cleaned_Data!$N$2:$N$236,"OK") -> 373600 | E7: =SUMIFS(Cleaned_Data!$M$2:$M$236,Cleaned_Data!$D$2:$D$236,$A7,Cleaned_Data!$B$2:$B$236,">="&E$2,Cleaned_Data!$B$2:$B$236,"<="&EOMONTH(E$2,0),Cleaned_Data!$N$2:$N$236,"OK") -> 264570 | F7: =SUMIFS(Cleaned_Data!$M$2:$M$236,Cleaned_Data!$D$2:$D$236,$A7,Cleaned_Data!$B$2:$B$236,">="&F$2,Cleaned_Data!$B$2:$B$236,"<="&EOMONTH(F$2,0),Cleaned_Data!$N$2:$N$236,"OK") -> 287050 | G7: =SUMIFS(Cleaned_Data!$M$2:$M$236,Cleaned_Data!$D$2:$D$236,$A7,Cleaned_Data!$B$2:$B$236,">="&G$2,Cleaned_Data!$B$2:$B$236,"<="&EOMONTH(G$2,0),Cleaned_Data!$N$2:$N$236,"OK") -> 264300

Sheet Pivot
A1: Revenue Pivot - Net Revenue by Region and Month
A3: Sum of Net Revenue | B3: Column Labels
A4: Row Labels | B4: January | C4: February | D4: March | E4: April | F4: May | G4: June | H4: July | I4: August | J4: September | K4: October | L4: November | M4: December | N4: NA | O4: Grand Total
A5: Central | B5: 424000 | C5: 491370 | D5: 627550 | E5: 264300 | F5: 56000 | J5: 5250 | L5: 1244732.5 | M5: 318675 | O5: 3431877.5
A6: East | B6: 195600 | C6: 609440 | D6: 419185 | E6: 683180 | F6: 13500 | G6: 115200 | I6: 17850 | J6: 144000 | L6: 775270 | M6: 157205 | O6: 3130430
A7: North | B7: 426670 | C7: 171327.5 | D7: 99140 | E7: 2966335 | F7: 57000 | G7: 19360 | H7: 67875 | K7: 84100 | L7: 687575 | M7: 381177.5 | N7: 1650 | O7: 4962210
A8: South | B8: 871157.5 | C8: 673875 | D8: 393610 | E8: 511050 | H8: 14875 | I8: 0 | J8: 31500 | K8: 19800 | L8: 393595 | M8: 274815 | O8: 3184277.5
A9: Unknown | B9: 3000 | C9: 565040 | D9: 94500 | F9: 56000 | K9: 23625 | L9: 8412.5 | M9: 165000 | O9: 915577.5
A10: West | B10: 411175 | C10: 509667.5 | D10: 1174500 | E10: 976732.5 | F10: 40500 | H10: 14000 | I10: 3600 | L10: 623750 | M10: 611437.5 | O10: 4365362.5
A11: Grand Total | B11: 2331602.5 | C11: 3020720 | D11: 2808485 | E11: 5401597.5 | F11: 223000 | G11: 134560 | H11: 96750 | I11: 21450 | J11: 180750 | K11: 127525 | L11: 3733335 | M11: 1908310 | N11: 1650 | O11: 19989735

Sheet Dashboard
A1: MIS Operations Dashboard
A3: Total Revenue | B3: Total Orders | C3: AOV | D3: Top Region
A4: =SUM(Analysis!C3:C7) -> 14135932 | B4: =SUM(Analysis!B3:B7) -> 149 | C4: =IFERROR(A4/B4,0) -> 94872.03 | D4: =INDEX(Analysis!A3:A7,MATCH(MAX(Analysis!C3:C7),Analysis!C3:C7,0)) -> West | H4: Month
H5: North | I5: Revenue
H6: Nov-2025 | I6: =SUMIFS(Cleaned_Data!$M:$M, Cleaned_Data!$D:$D, $H$5, Cleaned_Data!$B:$B, ">="&H6, Cleaned_Data!$B:$B, "<="&EOMONTH(H6,0), Cleaned_Data!$N:$N, "OK") -> 678075
H7: Dec-2025 | I7: =SUMIFS(Cleaned_Data!$M:$M, Cleaned_Data!$D:$D, $H$5, Cleaned_Data!$B:$B, ">="&H7, Cleaned_Data!$B:$B, "<="&EOMONTH(H7,0), Cleaned_Data!$N:$N, "OK") -> 350120
H8: Jan-2026 | I8: =SUMIFS(Cleaned_Data!$M:$M, Cleaned_Data!$D:$D, $H$5, Cleaned_Data!$B:$B, ">="&H8, Cleaned_Data!$B:$B, "<="&EOMONTH(H8,0), Cleaned_Data!$N:$N, "OK") -> 84670
H9: Feb-2026 | I9: =SUMIFS(Cleaned_Data!$M:$M, Cleaned_Data!$D:$D, $H$5, Cleaned_Data!$B:$B, ">="&H9, Cleaned_Data!$B:$B, "<="&EOMONTH(H9,0), Cleaned_Data!$N:$N, "OK") -> 117327.5
H10: Mar-2026 | I10: =SUMIFS(Cleaned_Data!$M:$M, Cleaned_Data!$D:$D, $H$5, Cleaned_Data!$B:$B, ">="&H10, Cleaned_Data!$B:$B, "<="&EOMONTH(H10,0), Cleaned_Data!$N:$N, "OK") -> 50690
H11: Apr-2026 | I11: =SUMIFS(Cleaned_Data!$M:$M, Cleaned_Data!$D:$D, $H$5, Cleaned_Data!$B:$B, ">="&H11, Cleaned_Data!$B:$B, "<="&EOMONTH(H11,0), Cleaned_Data!$N:$N, "OK") -> 1595310
